<?xml version="1.0" ?>
<!-- =================================================================================== -->
<!-- |    This document was autogenerated by xacro from /home/rtrk/OSuRV_s5a/s5a/s5a/ROS/s5a_ws/src/s5a_main/urdf/arm.urdf.xacro | -->
<!-- |    EDITING THIS FILE BY HAND IS NOT RECOMMENDED                                 | -->
<!-- =================================================================================== -->
<robot name="arm">
    <material name="alu">
        <!-- blue -->
        <color rgba="0 0 0.8 1" />
    </material>
    <material name="bearing">
        <!-- red -->
        <color rgba="0.8 0.0 0.0 1" />
    </material>
    <material name="wood">
        <!-- green -->
        <color rgba="0 0.8 0 1" />
    </material>
    <material name="alu_ee">
        <!-- blue -->
        <color rgba="0 0.8 0.8 1" />
    </material>
    <gazebo>
        <plugin filename="libgazebo_ros_control.so" name="ros_control">
            <!--robotNamespace>/</robotNamespace-->
            <!--robotSimType>gazebo_ros_control/DefaultRobotHWSim</robotSimType-->
        </plugin>
        <plugin name="gazebo_ros_control">
            <robotNamespace>/</robotNamespace>
        </plugin>
    </gazebo>
    <link name="world" />
    <joint name="fixjoint00_world" type="fixed">
        <parent link="world" />
        <child link="beam00_base" />
        <origin rpy="0.0 0.0 0.0" xyz="0.0 0.0 0.0" />
    </joint>
    <link name="beam00_base">
        <visual>
            <origin rpy="1.5707963267948966 0.0 1.5707963267948966" xyz="0.0 0.0 0.025" />
            <geometry>
                <box size="0.05 0.05 0.1" />
            </geometry>
            <material name="alu" />
        </visual>
        <collision>
            <origin rpy="1.5707963267948966 0.0 1.5707963267948966" xyz="0.0 0.0 0.025" />
            <geometry>
                <box size="0.05 0.05 0.1" />
            </geometry>
        </collision>
        <!-- TODO Calc -->
        <inertial>
            <origin rpy="0.0 0.0 0.0" xyz="0.0 0.0 0.0" />
            <mass value="0.0001" />
            <inertia ixx="0.03" ixy="0.0" ixz="0.0" iyy="0.03" iyz="0.0" izz="0.03" />
        </inertial>
    </link>
    <!-- TODO What is this anyway? -->
    <gazebo reference="beam00_base">
        <selfCollide>true</selfCollide>
    </gazebo>
    <joint name="weld00_base" type="fixed">
        <origin rpy="0.0 0.0 0.0" xyz="0.0 0.0 0.05" />
        <parent link="beam00_base" />
        <child link="bearing00_base" />
    </joint>
    <link name="bearing00_base">
        <visual>
            <origin rpy="0.0 0.0 0.0" xyz="0.0 0.0 0.005" />
            <geometry>
                <cylinder length="0.01" radius="0.015" />
            </geometry>
            <material name="bearing" />
        </visual>
        <collision>
            <origin rpy="0.0 0.0 0.0" xyz="0.0 0.0 0.005" />
            <geometry>
                <cylinder length="0.01" radius="0.03" />
            </geometry>
        </collision>
        <!-- TODO Calc -->
        <inertial>
            <origin rpy="0.0 0.0 0.0" xyz="0.0 0.0 0.0" />
            <mass value="0.00001" />
            <inertia ixx="0.03" ixy="0.0" ixz="0.0" iyy="0.03" iyz="0.0" izz="0.03" />
        </inertial>
    </link>
    <joint name="joint0_shoulder_pan" type="revolute">
        <axis xyz="0 0 1" />
        <limit effort="100.0" lower="-1.5707963267948966" upper="1.5707963267948966" velocity="100" />
        <!-- <safety_controller
				k_velocity="100.0"
			/> -->
        <origin rpy="0.0 0.0 0.0" xyz="0.0 0.0 0.01" />
        <parent link="bearing00_base" />
        <child link="beam0_shoulder" />
    </joint>
    <transmission name="joint0_shoulder_pan_trans">
        <type>transmission_interface/SimpleTransmission</type>
        <joint name="joint0_shoulder_pan">
            <hardwareInterface>hardware_interface/EffortJointInterface</hardwareInterface>
        </joint>
        <actuator name="joint0_shoulder_pan_motor">
            <mechanicalReduction>1</mechanicalReduction>
            <hardwareInterface>hardware_interface/EffortJointInterface</hardwareInterface>
        </actuator>
    </transmission>
    <link name="beam0_shoulder">
        <visual>
            <origin rpy="0.0 0.0 0.0" xyz="0.0 -0.025 0.1" />
            <geometry>
                <box size="0.05 0.05 0.2" />
            </geometry>
            <material name="alu" />
        </visual>
        <collision>
            <origin rpy="0.0 0.0 0.0" xyz="0.0 -0.025 0.1" />
            <geometry>
                <box size="0.05 0.05 0.2" />
            </geometry>
        </collision>
        <!-- TODO Calc -->
        <inertial>
            <origin rpy="0.0 0.0 0.0" xyz="0.0 0.0 0.0" />
            <mass value="0.0001" />
            <inertia ixx="0.03" ixy="0.0" ixz="0.0" iyy="0.03" iyz="0.0" izz="0.03" />
        </inertial>
    </link>
    <!-- TODO What is this anyway? -->
    <gazebo reference="beam0_shoulder">
        <selfCollide>true</selfCollide>
    </gazebo>
    <joint name="weld0_shoulder" type="fixed">
        <origin rpy="-1.5707963267948966 0.0 0.0" xyz="0.0 0.0 0.17500000000000002" />
        <parent link="beam0_shoulder" />
        <child link="bearing0_shoulder" />
    </joint>
    <link name="bearing0_shoulder">
        <visual>
            <origin rpy="0.0 0.0 0.0" xyz="0.0 0.0 0.005" />
            <geometry>
                <cylinder length="0.01" radius="0.015" />
            </geometry>
            <material name="bearing" />
        </visual>
        <collision>
            <origin rpy="0.0 0.0 0.0" xyz="0.0 0.0 0.005" />
            <geometry>
                <cylinder length="0.01" radius="0.03" />
            </geometry>
        </collision>
        <!-- TODO Calc -->
        <inertial>
            <origin rpy="0.0 0.0 0.0" xyz="0.0 0.0 0.0" />
            <mass value="0.00001" />
            <inertia ixx="0.03" ixy="0.0" ixz="0.0" iyy="0.03" iyz="0.0" izz="0.03" />
        </inertial>
    </link>
    <joint name="joint1_shoulder_lift" type="revolute">
        <axis xyz="0 0 1" />
        <limit effort="100.0" lower="-1.5707963267948966" upper="0.7853981633974483" velocity="100" />
        <!-- <safety_controller
				k_velocity="100.0"
			/> -->
        <origin rpy="0.0 0.0 3.141592653589793" xyz="0.0 0.0 0.01" />
        <parent link="bearing0_shoulder" />
        <child link="beam1_upper_arm" />
    </joint>
    <transmission name="joint1_shoulder_lift_trans">
        <type>transmission_interface/SimpleTransmission</type>
        <joint name="joint1_shoulder_lift">
            <hardwareInterface>hardware_interface/EffortJointInterface</hardwareInterface>
        </joint>
        <actuator name="joint1_shoulder_lift_motor">
            <mechanicalReduction>1</mechanicalReduction>
            <hardwareInterface>hardware_interface/EffortJointInterface</hardwareInterface>
        </actuator>
    </transmission>
    <link name="beam1_upper_arm">
        <visual>
            <origin rpy="1.5707963267948966 0.0 0.0" xyz="0.0 0.225 0.025" />
            <geometry>
                <box size="0.05 0.05 0.5" />
            </geometry>
            <material name="alu" />
        </visual>
        <collision>
            <origin rpy="1.5707963267948966 0.0 0.0" xyz="0.0 0.225 0.025" />
            <geometry>
                <box size="0.05 0.05 0.5" />
            </geometry>
        </collision>
        <!-- TODO Calc -->
        <inertial>
            <origin rpy="0.0 0.0 0.0" xyz="0.0 0.0 0.0" />
            <mass value="0.0001" />
            <inertia ixx="0.03" ixy="0.0" ixz="0.0" iyy="0.03" iyz="0.0" izz="0.03" />
        </inertial>
    </link>
    <!-- TODO What is this anyway? -->
    <gazebo reference="beam1_upper_arm">
        <selfCollide>true</selfCollide>
    </gazebo>
    <joint name="weld1_upper_arm" type="fixed">
        <origin rpy="0.0 3.141592653589793 -1.5707963267948966" xyz="0.0 0.45 0.0" />
        <parent link="beam1_upper_arm" />
        <child link="bearing1_upper_arm" />
    </joint>
    <link name="bearing1_upper_arm">
        <visual>
            <origin rpy="0.0 0.0 0.0" xyz="0.0 0.0 0.005" />
            <geometry>
                <cylinder length="0.01" radius="0.015" />
            </geometry>
            <material name="bearing" />
        </visual>
        <collision>
            <origin rpy="0.0 0.0 0.0" xyz="0.0 0.0 0.005" />
            <geometry>
                <cylinder length="0.01" radius="0.03" />
            </geometry>
        </collision>
        <!-- TODO Calc -->
        <inertial>
            <origin rpy="0.0 0.0 0.0" xyz="0.0 0.0 0.0" />
            <mass value="0.00001" />
            <inertia ixx="0.03" ixy="0.0" ixz="0.0" iyy="0.03" iyz="0.0" izz="0.03" />
        </inertial>
    </link>
    <joint name="joint2_elbow" type="revolute">
        <axis xyz="0 0 1" />
        <limit effort="100.0" lower="-0.8726646259971648" upper="1.3962634015954636" velocity="100" />
        <!-- <safety_controller
				k_velocity="100.0"
			/> -->
        <origin rpy="0.0 0.0 3.141592653589793" xyz="0.0 0.0 0.01" />
        <parent link="bearing1_upper_arm" />
        <child link="beam2_forearm" />
    </joint>
    <transmission name="joint2_elbow_trans">
        <type>transmission_interface/SimpleTransmission</type>
        <joint name="joint2_elbow">
            <hardwareInterface>hardware_interface/EffortJointInterface</hardwareInterface>
        </joint>
        <actuator name="joint2_elbow_motor">
            <mechanicalReduction>1</mechanicalReduction>
            <hardwareInterface>hardware_interface/EffortJointInterface</hardwareInterface>
        </actuator>
    </transmission>
    <link name="beam2_forearm">
        <visual>
            <origin rpy="1.5707963267948966 0.0 0.0" xyz="0.0 0.18 0.02" />
            <geometry>
                <box size="0.04 0.04 0.4" />
            </geometry>
            <material name="alu" />
        </visual>
        <collision>
            <origin rpy="1.5707963267948966 0.0 0.0" xyz="0.0 0.18 0.02" />
            <geometry>
                <box size="0.04 0.04 0.4" />
            </geometry>
        </collision>
        <!-- TODO Calc -->
        <inertial>
            <origin rpy="0.0 0.0 0.0" xyz="0.0 0.0 0.0" />
            <mass value="0.0001" />
            <inertia ixx="0.03" ixy="0.0" ixz="0.0" iyy="0.03" iyz="0.0" izz="0.03" />
        </inertial>
    </link>
    <!-- TODO What is this anyway? -->
    <gazebo reference="beam2_forearm">
        <selfCollide>true</selfCollide>
    </gazebo>
    <joint name="weld2_upper_arm" type="fixed">
        <origin rpy="0.0 3.141592653589793 -1.5707963267948966" xyz="0.0 0.35000000000000003 0.0" />
        <parent link="beam2_forearm" />
        <child link="bearing2_upper_arm" />
    </joint>
    <link name="bearing2_upper_arm">
        <visual>
            <origin rpy="0.0 0.0 0.0" xyz="0.0 0.0 0.005" />
            <geometry>
                <cylinder length="0.01" radius="0.015" />
            </geometry>
            <material name="bearing" />
        </visual>
        <collision>
            <origin rpy="0.0 0.0 0.0" xyz="0.0 0.0 0.005" />
            <geometry>
                <cylinder length="0.01" radius="0.03" />
            </geometry>
        </collision>
        <!-- TODO Calc -->
        <inertial>
            <origin rpy="0.0 0.0 0.0" xyz="0.0 0.0 0.0" />
            <mass value="0.00001" />
            <inertia ixx="0.03" ixy="0.0" ixz="0.0" iyy="0.03" iyz="0.0" izz="0.03" />
        </inertial>
    </link>
    <joint name="joint3_wrist_flap" type="revolute">
        <axis xyz="0 0 1" />
        <limit effort="100.0" lower="-0.8726646259971648" upper="1.3962634015954636" velocity="100" />
        <!-- <safety_controller
				k_velocity="100.0"
			/> -->
        <origin rpy="0.0 0.0 3.141592653589793" xyz="0.0 0.0 0.01" />
        <parent link="bearing2_upper_arm" />
        <child link="beam3_forearm" />
    </joint>
    <transmission name="joint3_wrist_flap_trans">
        <type>transmission_interface/SimpleTransmission</type>
        <joint name="joint3_wrist_flap">
            <hardwareInterface>hardware_interface/EffortJointInterface</hardwareInterface>
        </joint>
        <actuator name="joint3_wrist_flap_motor">
            <mechanicalReduction>1</mechanicalReduction>
            <hardwareInterface>hardware_interface/EffortJointInterface</hardwareInterface>
        </actuator>
    </transmission>
    <link name="beam3_forearm">
        <visual>
            <origin rpy="1.5707963267948966 0.0 0.0" xyz="0.0 0.03 0.02" />
            <geometry>
                <box size="0.04 0.04 0.1" />
            </geometry>
            <material name="alu" />
        </visual>
        <collision>
            <origin rpy="1.5707963267948966 0.0 0.0" xyz="0.0 0.03 0.02" />
            <geometry>
                <box size="0.04 0.04 0.1" />
            </geometry>
        </collision>
        <!-- TODO Calc -->
        <inertial>
            <origin rpy="0.0 0.0 0.0" xyz="0.0 0.0 0.0" />
            <mass value="0.0001" />
            <inertia ixx="0.03" ixy="0.0" ixz="0.0" iyy="0.03" iyz="0.0" izz="0.03" />
        </inertial>
    </link>
    <!-- TODO What is this anyway? -->
    <gazebo reference="beam3_forearm">
        <selfCollide>true</selfCollide>
    </gazebo>
    <joint name="weld3_arm" type="fixed">
        <origin rpy="1.5707963267948966 0.0 0.0" xyz="0.0 0.08 0.02" />
        <parent link="beam3_forearm" />
        <child link="bearing3_upper_arm" />
    </joint>
    <link name="bearing3_upper_arm">
        <visual>
            <origin rpy="0.0 0.0 0.0" xyz="0.0 0.0 0.001" />
            <geometry>
                <cylinder length="0.01" radius="0.015" />
            </geometry>
            <material name="bearing" />
        </visual>
        <collision>
            <origin rpy="0.0 0.0 0.0" xyz="0.0 0.0 0.001" />
            <geometry>
                <cylinder length="0.01" radius="0.03" />
            </geometry>
        </collision>
        <!-- TODO Calc -->
        <inertial>
            <origin rpy="0.0 0.0 0.0" xyz="0.0 0.0 0.0" />
            <mass value="0.00001" />
            <inertia ixx="0.03" ixy="0.0" ixz="0.0" iyy="0.03" iyz="0.0" izz="0.03" />
        </inertial>
    </link>
    <joint name="joint4_wrist_rot" type="revolute">
        <axis xyz="0 0 1" />
        <limit effort="100.0" lower="-1.5707963267948966" upper="1.5707963267948966" velocity="100" />
        <!-- <safety_controller
				k_velocity="100.0"
			/> -->
        <origin rpy="0.0 1.5707963267948966 0.0" xyz="0.0 0.0 0.01" />
        <parent link="bearing3_upper_arm" />
        <child link="hand_ee" />
    </joint>
    <transmission name="joint4_wrist_rot_trans">
        <type>transmission_interface/SimpleTransmission</type>
        <joint name="joint4_wrist_rot">
            <hardwareInterface>hardware_interface/EffortJointInterface</hardwareInterface>
        </joint>
        <actuator name="joint4_wrist_rot_motor">
            <mechanicalReduction>1</mechanicalReduction>
            <hardwareInterface>hardware_interface/EffortJointInterface</hardwareInterface>
        </actuator>
    </transmission>
    <link name="hand_ee">
        <visual>
            <origin rpy="3.141592653589793 0.0 3.141592653589793" xyz="0.015 0.0 0.0" />
            <geometry>
                <box size="0.04 0.04 0.03" />
            </geometry>
            <material name="alu_ee" />
        </visual>
        <collision>
            <origin rpy="3.141592653589793 0.0 3.141592653589793" xyz="0.015 0.0 0.0" />
            <geometry>
                <box size="0.04 0.04 0.03" />
            </geometry>
        </collision>
        <!-- TODO Calc -->
        <inertial>
            <origin rpy="0.0 0.0 0.0" xyz="0.0 0.0 0.0" />
            <mass value="0.0001" />
            <inertia ixx="0.03" ixy="0.0" ixz="0.0" iyy="0.03" iyz="0.0" izz="0.03" />
        </inertial>
    </link>
    <!-- TODO What is this anyway? -->
    <gazebo reference="hand_ee">
        <selfCollide>true</selfCollide>
    </gazebo>
    <joint name="joint5_index_finger" type="revolute">
        <axis xyz="0 0 1" />
        <limit effort="100.0" lower="0.0" upper="1.2217304763960306" velocity="100" />
        <!-- <safety_controller
				k_velocity="100.0"
			/> -->
        <origin rpy="0.0 0.0 -1.5707963267948966" xyz="0.015 0.01 -0.02" />
        <parent link="hand_ee" />
        <child link="beam3_index_finger" />
    </joint>
    <transmission name="joint5_index_finger_trans">
        <type>transmission_interface/SimpleTransmission</type>
        <joint name="joint5_index_finger">
            <hardwareInterface>hardware_interface/EffortJointInterface</hardwareInterface>
        </joint>
        <actuator name="joint5_index_finger_motor">
            <mechanicalReduction>1</mechanicalReduction>
            <hardwareInterface>hardware_interface/EffortJointInterface</hardwareInterface>
        </actuator>
    </transmission>
    <link name="beam3_index_finger">
        <visual>
            <origin rpy="1.5707963267948966 0.0 0.0" xyz="0.0 0.04 -0.0183" />
            <geometry>
                <box size="0.02 0.02 0.08" />
            </geometry>
            <material name="wood" />
        </visual>
        <collision>
            <origin rpy="1.5707963267948966 0.0 0.0" xyz="0.0 0.04 -0.0183" />
            <geometry>
                <box size="0.02 0.02 0.08" />
            </geometry>
        </collision>
        <!-- TODO Calc -->
        <inertial>
            <origin rpy="0.0 0.0 0.0" xyz="0.0 0.0 0.0" />
            <mass value="0.0001" />
            <inertia ixx="0.03" ixy="0.0" ixz="0.0" iyy="0.03" iyz="0.0" izz="0.03" />
        </inertial>
    </link>
    <!-- TODO What is this anyway? -->
    <gazebo reference="beam3_index_finger">
        <selfCollide>true</selfCollide>
    </gazebo>
    <joint name="joint6_middle_finger" type="revolute">
        <axis xyz="0 0 1" />
        <limit effort="100.0" lower="0.0" upper="1.2217304763960306" velocity="100" />
        <!-- <safety_controller
				k_velocity="100.0"
			/> -->
        <origin rpy="0.0 3.141592653589793 1.5707963267948966" xyz="0.015 -0.01 -0.02" />
        <parent link="hand_ee" />
        <child link="beam4_middle_finger" />
    </joint>
    <transmission name="joint6_middle_finger_trans">
        <type>transmission_interface/SimpleTransmission</type>
        <joint name="joint6_middle_finger">
            <hardwareInterface>hardware_interface/EffortJointInterface</hardwareInterface>
        </joint>
        <actuator name="joint6_middle_finger_motor">
            <mechanicalReduction>1</mechanicalReduction>
            <hardwareInterface>hardware_interface/EffortJointInterface</hardwareInterface>
        </actuator>
    </transmission>
    <link name="beam4_middle_finger">
        <visual>
            <origin rpy="1.5707963267948966 0.0 0.0" xyz="0.0 -0.04 0.0183" />
            <geometry>
                <box size="0.02 0.02 0.08" />
            </geometry>
            <material name="wood" />
        </visual>
        <collision>
            <origin rpy="1.5707963267948966 0.0 0.0" xyz="0.0 -0.04 0.0183" />
            <geometry>
                <box size="0.02 0.02 0.08" />
            </geometry>
        </collision>
        <!-- TODO Calc -->
        <inertial>
            <origin rpy="0.0 0.0 0.0" xyz="0.0 0.0 0.0" />
            <mass value="0.0001" />
            <inertia ixx="0.03" ixy="0.0" ixz="0.0" iyy="0.03" iyz="0.0" izz="0.03" />
        </inertial>
    </link>
    <!-- TODO What is this anyway? -->
    <gazebo reference="beam4_middle_finger">
        <selfCollide>true</selfCollide>
    </gazebo>
</robot>

